WARNING  urllib3.connectionpool:connectionpool.py:812 Retrying (Retry(total=2, connect=None, read=None, redirect=None, status=None)) after connection broken by 'NewConnectionError('<urllib3.connection.HTTPConnection object at 0x7fea7fb9eaa0>: Failed to establish a new connection: [Errno 111] Connection refused')': /wd/hub/session
WARNING  urllib3.connectionpool:connectionpool.py:812 Retrying (Retry(total=1, connect=None, read=None, redirect=None, status=None)) after connection broken by 'NewConnectionError('<urllib3.connection.HTTPConnection object at 0x7fea7fb9e920>: Failed to establish a new connection: [Errno 111] Connection refused')': /wd/hub/session
WARNING  urllib3.connectionpool:connectionpool.py:812 Retrying (Retry(total=0, connect=None, read=None, redirect=None, status=None)) after connection broken by 'NewConnectionError('<urllib3.connection.HTTPConnection object at 0x7fea7fb9ea40>: Failed to establish a new connection: [Errno 111] Connection refused')': /wd/hub/session
WARNING  urllib3.connectionpool:connectionpool.py:812 Retrying (Retry(total=2, connect=None, read=None, redirect=None, status=None)) after connection broken by 'NewConnectionError('<urllib3.connection.HTTPConnection object at 0x7fea7fb9dd20>: Failed to establish a new connection: [Errno 111] Connection refused')': /wd/hub/session
WARNING  urllib3.connectionpool:connectionpool.py:812 Retrying (Retry(total=1, connect=None, read=None, redirect=None, status=None)) after connection broken by 'NewConnectionError('<urllib3.connection.HTTPConnection object at 0x7fea7fb9ded0>: Failed to establish a new connection: [Errno 111] Connection refused')': /wd/hub/session
WARNING  urllib3.connectionpool:connectionpool.py:812 Retrying (Retry(total=0, connect=None, read=None, redirect=None, status=None)) after connection broken by 'NewConnectionError('<urllib3.connection.HTTPConnection object at 0x7fea7fb9dc00>: Failed to establish a new connection: [Errno 111] Connection refused')': /wd/hub/session
WARNING  urllib3.connectionpool:connectionpool.py:812 Retrying (Retry(total=2, connect=None, read=None, redirect=None, status=None)) after connection broken by 'NewConnectionError('<urllib3.connection.HTTPConnection object at 0x7fea7fb9d0c0>: Failed to establish a new connection: [Errno 111] Connection refused')': /wd/hub/session
WARNING  urllib3.connectionpool:connectionpool.py:812 Retrying (Retry(total=1, connect=None, read=None, redirect=None, status=None)) after connection broken by 'NewConnectionError('<urllib3.connection.HTTPConnection object at 0x7fea7fb9d150>: Failed to establish a new connection: [Errno 111] Connection refused')': /wd/hub/session
WARNING  urllib3.connectionpool:connectionpool.py:812 Retrying (Retry(total=0, connect=None, read=None, redirect=None, status=None)) after connection broken by 'NewConnectionError('<urllib3.connection.HTTPConnection object at 0x7fea7fb9d870>: Failed to establish a new connection: [Errno 111] Connection refused')': /wd/hub/session
WARNING  urllib3.connectionpool:connectionpool.py:812 Retrying (Retry(total=2, connect=None, read=None, redirect=None, status=None)) after connection broken by 'NewConnectionError('<urllib3.connection.HTTPConnection object at 0x7fea7fb9e290>: Failed to establish a new connection: [Errno 111] Connection refused')': /wd/hub/session
WARNING  urllib3.connectionpool:connectionpool.py:812 Retrying (Retry(total=1, connect=None, read=None, redirect=None, status=None)) after connection broken by 'NewConnectionError('<urllib3.connection.HTTPConnection object at 0x7fea7fb9ff10>: Failed to establish a new connection: [Errno 111] Connection refused')': /wd/hub/session
WARNING  urllib3.connectionpool:connectionpool.py:812 Retrying (Retry(total=0, connect=None, read=None, redirect=None, status=None)) after connection broken by 'NewConnectionError('<urllib3.connection.HTTPConnection object at 0x7fea7fb9fd90>: Failed to establish a new connection: [Errno 111] Connection refused')': /wd/hub/session
WARNING  urllib3.connectionpool:connectionpool.py:812 Retrying (Retry(total=2, connect=None, read=None, redirect=None, status=None)) after connection broken by 'NewConnectionError('<urllib3.connection.HTTPConnection object at 0x7fea7fb9f700>: Failed to establish a new connection: [Errno 111] Connection refused')': /wd/hub/session
WARNING  urllib3.connectionpool:connectionpool.py:812 Retrying (Retry(total=1, connect=None, read=None, redirect=None, status=None)) after connection broken by 'NewConnectionError('<urllib3.connection.HTTPConnection object at 0x7fea7fb9f520>: Failed to establish a new connection: [Errno 111] Connection refused')': /wd/hub/session
WARNING  urllib3.connectionpool:connectionpool.py:812 Retrying (Retry(total=0, connect=None, read=None, redirect=None, status=None)) after connection broken by 'NewConnectionError('<urllib3.connection.HTTPConnection object at 0x7fea7fb9d990>: Failed to establish a new connection: [Errno 111] Connection refused')': /wd/hub/session
WARNING  urllib3.connectionpool:connectionpool.py:812 Retrying (Retry(total=2, connect=None, read=None, redirect=None, status=None)) after connection broken by 'NewConnectionError('<urllib3.connection.HTTPConnection object at 0x7fea7fb89120>: Failed to establish a new connection: [Errno 111] Connection refused')': /wd/hub/session
WARNING  urllib3.connectionpool:connectionpool.py:812 Retrying (Retry(total=1, connect=None, read=None, redirect=None, status=None)) after connection broken by 'NewConnectionError('<urllib3.connection.HTTPConnection object at 0x7fea7fb88d90>: Failed to establish a new connection: [Errno 111] Connection refused')': /wd/hub/session
WARNING  urllib3.connectionpool:connectionpool.py:812 Retrying (Retry(total=0, connect=None, read=None, redirect=None, status=None)) after connection broken by 'NewConnectionError('<urllib3.connection.HTTPConnection object at 0x7fea7fb893f0>: Failed to establish a new connection: [Errno 111] Connection refused')': /wd/hub/session
WARNING  urllib3.connectionpool:connectionpool.py:812 Retrying (Retry(total=2, connect=None, read=None, redirect=None, status=None)) after connection broken by 'NewConnectionError('<urllib3.connection.HTTPConnection object at 0x7fea7fb88910>: Failed to establish a new connection: [Errno 111] Connection refused')': /wd/hub/session
WARNING  urllib3.connectionpool:connectionpool.py:812 Retrying (Retry(total=1, connect=None, read=None, redirect=None, status=None)) after connection broken by 'NewConnectionError('<urllib3.connection.HTTPConnection object at 0x7fea7fb884c0>: Failed to establish a new connection: [Errno 111] Connection refused')': /wd/hub/session
WARNING  urllib3.connectionpool:connectionpool.py:812 Retrying (Retry(total=0, connect=None, read=None, redirect=None, status=None)) after connection broken by 'NewConnectionError('<urllib3.connection.HTTPConnection object at 0x7fea7fb88bb0>: Failed to establish a new connection: [Errno 111] Connection refused')': /wd/hub/session
WARNING  urllib3.connectionpool:connectionpool.py:812 Retrying (Retry(total=2, connect=None, read=None, redirect=None, status=None)) after connection broken by 'NewConnectionError('<urllib3.connection.HTTPConnection object at 0x7fea7fb9f370>: Failed to establish a new connection: [Errno 111] Connection refused')': /wd/hub/session
WARNING  urllib3.connectionpool:connectionpool.py:812 Retrying (Retry(total=1, connect=None, read=None, redirect=None, status=None)) after connection broken by 'NewConnectionError('<urllib3.connection.HTTPConnection object at 0x7fea7fb89d50>: Failed to establish a new connection: [Errno 111] Connection refused')': /wd/hub/session
WARNING  urllib3.connectionpool:connectionpool.py:812 Retrying (Retry(total=0, connect=None, read=None, redirect=None, status=None)) after connection broken by 'NewConnectionError('<urllib3.connection.HTTPConnection object at 0x7fea7fb89bd0>: Failed to establish a new connection: [Errno 111] Connection refused')': /wd/hub/session
WARNING  urllib3.connectionpool:connectionpool.py:812 Retrying (Retry(total=2, connect=None, read=None, redirect=None, status=None)) after connection broken by 'NewConnectionError('<urllib3.connection.HTTPConnection object at 0x7fea7fb896c0>: Failed to establish a new connection: [Errno 111] Connection refused')': /wd/hub/session
WARNING  urllib3.connectionpool:connectionpool.py:812 Retrying (Retry(total=1, connect=None, read=None, redirect=None, status=None)) after connection broken by 'NewConnectionError('<urllib3.connection.HTTPConnection object at 0x7fea7fb8bd60>: Failed to establish a new connection: [Errno 111] Connection refused')': /wd/hub/session
WARNING  urllib3.connectionpool:connectionpool.py:812 Retrying (Retry(total=0, connect=None, read=None, redirect=None, status=None)) after connection broken by 'NewConnectionError('<urllib3.connection.HTTPConnection object at 0x7fea7fb8bc40>: Failed to establish a new connection: [Errno 111] Connection refused')': /wd/hub/session